Workbook
Name area_vis_lv2: Constraint!$E$21
Name area_vis_lv21: Constraint!$F$21
Name area_vis_lv3: Constraint!$F$22
Name areavisend: [1]Constants!$F$20
Name areavisend: [1]Constants!$F$20
Name areavisend: [1]Constants!$F$20
Name areavisend: [1]Constants!$F$20
Name areavisend: [2]Constants!$F$20
Name areavislv2: [1]Constants!$F$19
Name areavislv2: [1]Constants!$F$19
Name areavislv2: [1]Constants!$F$19
Name areavislv2: [1]Constants!$F$19
Name areavislv2: Constraint!$F$21
Name areavislv3: [1]Constants!$F$21
Name areavislv3: [1]Constants!$F$21
Name areavislv3: [1]Constants!$F$21
Name areavislv3: [1]Constants!$F$21
Name areavislv3: [2]Constants!$F$21
Name distviscodeend: [1]Constants!$F$24
Name distviscodeend: [1]Constants!$F$24
Name distviscodeend: [1]Constants!$F$24
Name distviscodeend: [1]Constants!$F$24
Name distviscodeend: [2]Constants!$F$24
Name distviscodeendend: [1]Constants!$F$25
Name distviscodeendend: [1]Constants!$F$25
Name distviscodeendend: [1]Constants!$F$25
Name distviscodeendend: [1]Constants!$F$25
Name distviscodeendend: [2]Constants!$F$25
Name distviscodestart: [1]Constants!$F$23
Name distviscodestart: [1]Constants!$F$23
Name distviscodestart: [1]Constants!$F$23
Name distviscodestart: [1]Constants!$F$23
Name distviscodestart: [2]Constants!$F$23
Name distvisor: [1]Constants!$F$22
Name distvisor: [1]Constants!$F$22
Name distvisor: [1]Constants!$F$22
Name distvisor: [1]Constants!$F$22
Name distvisor: [2]Constants!$F$22
Name EndLV4: Constraint!$F$23
Name listend: [1]Constants!$F$6
Name listend: [1]Constants!$F$6
Name listend: [1]Constants!$F$6
Name listend: [1]Constants!$F$6
Name listend: Constraint!$F$6
Name listla: [1]Constants!$F$5
Name listla: [1]Constants!$F$5
Name listla: [1]Constants!$F$5
Name listla: [1]Constants!$F$5
Name listla: Constraint!$F$5
Name listlareport: [1]Constants!$F$4
Name listlareport: [1]Constants!$F$4
Name listlareport: [1]Constants!$F$4
Name listlareport: [1]Constants!$F$4
Name listlareport: Constraint!$F$4
Name listlat: Constraint!$F$5
Name liststart: [1]Constants!$F$3
Name liststart: [1]Constants!$F$3
Name liststart: [1]Constants!$F$3
Name liststart: [1]Constants!$F$3
Name liststart: Constraint!$F$3

Sheet Instructions
L2: Created
L3: Last Reviewed JTI
L4: Last Reviewed CSD
B6: 1. This is a working document stored in the cloud for JTI-NBE core questionnaire for the Trade Census
B7: 2. All latest changes, agreements will be captured and tracked in this central document
B8: 3. This will be the base for the programing of the core questionnaire
B10: The template is divided in sections that you will find back in the questionnaire. Color Coding Bellow.
B12: In every section there are columns for questions / comments / observation at then end (CSD/Dev Team) Cells highlighted in yellow require attention / answer
C14: System or instructions sections
C15: Survey Sections
C16: Tables of lists, SKU, market customizable sections
C17: System rules (Anomalies, Rejections, Field Back Checks…)
C18: Current Template Used for
C19: Qualitative follow-up questionnaire for Consummer & Custommer Insight & Distributor Deep Dive
B21: Overall Open Topics / Questions
B22: For specific questions on survey areas please use the specified column for this in the relevant section
B23: Question | F23: Status | G23: Response

Sheet Profile
I1: QUESTIONS
A2: ID | B2: Visibility rule | C2: QUESTION WORDING EN | D2: Reporting LABEL | E2: ANSWER TYPE | F2: ANSWER OPTIONS | G2: NOTES SYSTEM | H2: NOTES REPORTING | I2: CSD | J2: Dev-team | K2: Dev-team
A3: Section
A4: P-10 | C4: Surname | D4: =A4&" "&C4 -> P-10 Surname | E4: TEXT | F4: Automatic | G4: From the back office setup
A5: P-20 | C5: Name | D5: =A5&" "&C5 -> P-20 Name | E5: TEXT | F5: Automatic | H5: Use in Field Management Dashboard
A6: P-30 | C6: Enumerator Code | D6: =A6&" "&C6 -> P-30 Enumerator Code | E6: NUMERIC | F6: Automatic | H6: Use in Field Management Dashboard
A7: P-40 | C7: Supervisor Code | D7: =A7&" "&C7 -> P-40 Supervisor Code | E7: NUMERIC | F7: Automatic | H7: Use in Field Management Dashboard
A8: P-50 | C8: Date | D8: =A8&" "&C8 -> P-50 Date | E8: NUMERIC | G8: System - Automatic | H8: Use in Field Management Dashboard
A9: P-60 | C9: Telephone number | D9: =A9&" "&C9 -> P-60 Telephone number | E9: NUMERIC | F9: Automatic
A10: P-70 | C10: Time stamp START Interview | D10: P-70 Interview Start | E10: NUMERIC | F10: Automatic | G10: System - Automatic | H10: Important for measurement of quality of work

Sheet Obs
A1: ID | B1: Observation | C1: Included in JSON | D1: Needs to be modified in JSON
A2: Area
A3: A-10 | B3: Province is asked in the next section, this question should ask for the city | C3: YES | D3: NO
A4: A-20 | C4: YES | D4: NO
A5: A-30 | B5: Used to say Barangay, now Kecamatan, which is the administrative division name for Inodnesia | C5: YES | D5: YES
A6: Need to move quesiton O-30 to this section
A7: Outlet Details
A8: O-10 | C8: YES | D8: NO
A9: O-20 | C9: YES | D9: NO
A10: O-30 | B10: Falls in their scope of work | C10: NO | D10: YES
A11: O-40 | C11: YES | D11: NO
A12: O-50 | B12: Evaluate how important or if the enumerated area its valid in Indonesia | C12: YES | D12: MAYBE
A13: O-60 | B13: Falls in their scope of work | C13: NO | D13: YES
A14: O-70 | B14: Asks for the complete address of the Outlet, unnecessary, all the info required is asked question by question | C14: NO | D14: NO
A15: O-80 | B15: Included in their scope, but asked in the area part | C15: NO | D15: NO
A16: No ID yet | B16: RT/RW (Rukun Warga=Village, RT=Neighborhoods?) reffering to a more detailed description of the administrative areas of Indonesia, unnecessary | C16: NO | D16: NO
A17: No ID yet | B17: Number, reffers to phone number? not sure what they mean by that, unncessary | C17: NO | D17: NO
A18: No ID yet | B18: Postal Code not in scope, unnecessary | C18: NO | D18: NO
A19: O-90 | B19: Falls in their scope of work | C19: NO | D19: YES
A20: Additional comment | B20: "Insert outlet's phone number (1. Landline first before mobile)" Guess he reffers to ask for two phone numbers, not sure why?, unnecessary, maybe just ask for one or the other
A21: Interview Start
A22: I-10 | C22: YES | D22: YES
A23: I-20 | B23: Changed the order of questions? First giving the I-40 Should ask for the person who's being interviewed | C23: YES | D23: NO
A24: I-30 | B24: Changed the order of questions? Here should be the introduction | C24: YES | D24: NO
A25: I-31 | B25: Missing this part of the intro, check the part of the company's name | C25: YES | D25: YES
A26: I-40 | B26: Missing | C26: YES | D26: NO
A27: I-50 | B27: Hidden previously, might need to be change to "liquour" so it falls in scope | C27: NO | D27: YES
A28: I-60 | B28: Hidden previously, falls in scope | C28: NO | D28: YES
A29: I-70 | B29: Hidden previously, falls in scope | C29: NO | D29: YES
A30: I-80 | B30: Hidden previously, falls in scope | C30: NO | D30: YES
A31: I-90 | B31: Erased by user | C31: YES | D31: NO
A32: I-100 | B32: Falls in their scope of work, but need to verify the classification | C32: NO | D32: YES
A33: I-110 | B33: Hidden before, but might be unnecessary as already asked in Outlet details | C33: YES | D33: MAYBE
A34: I-120 | B34: Hidden before | C34: YES | D34: NO
... A41: I-139 | B41: Erased by user | C41: YES | D41: NO
A42: (Retail)Marketing
A43: M-1 | C43: YES | D43: NO
A44: M-101 | B44: Moved from one section to the next
A45: M-10 | C45: YES | D45: NO
A46: M-20 | B46: Falls into scope, needs to be added | C46: NO | D46: YES
...

Sheet Area
A1: Question fields | G1: Answer fields | J1: Backoffice | M1: Comments
A2: ID | B2: Visibility rule | C2: QUESTION WORDING EN | D2: QUESTION WORDING FRENCH | E2: Wording change | F2: Question Priority 1 Keep 0 Discuss -1 remove ? | G2: Reporting LABEL | H2: ANSWER TYPE | I2: ANSWER OPTIONS | J2: Visible ENUMERATOR | K2: VISIBLE BC | L2: PREFILLED FOR BC | M2: ___ | N2: CSD | O2: Dev-team
A3: Section | D3: Dans quelle region se trouve le point de vente ? | F3: 1 | G3: A-10 Region | H3: SINGLE SELECTION
A4: A-10 | C4: What region are you located? | D4: Dans quelle region se trouve le point de vente ? | F4: 1 | G4: A-10 Region | H4: SINGLE SELECTION | I4: Region | J4: Yes | K4: Yes | L4: Yes
A5: A-20 | C5: What prefecture are you located? | D5: Dans quel département se trouve le point de vente ? | F5: 1 | G5: A-20 Prefecture | H5: SINGLE SELECTION | I5: Prefecture | J5: Yes | K5: Yes | L5: Yes
A6: A-30 | C6: What sub-prefecture/commune are you located? | D6: Dans quelle commune se trouve le point de vente ? | F6: 1 | G6: A-30 Sub-prefecture/Commune | H6: SINGLE SELECTION | I6: Sub-prefecture/Commune | J6: Yes | K6: Yes | L6: Yes
A7: A-40 | C7: What quartier are you located? | D7: Dans quel quartier se trouve le point de vente ? | F7: 1 | G7: A-40 Suburb | H7: SINGLE SELECTION | I7: Store Location Type | J7: Yes | K7: Yes | L7: Yes
A8: A-50 | C8: What is the block code? | F8: -1 | G8: A-50 Block | H8: SINGLE SELECTION | I8: Open text field | J8: Yes | K8: Yes | L8: Yes
A9: A-60 | C9: What is the sub-block code? | F9: -1 | G9: A-60 Subbolck | H9: SINGLE SELECTION | I9: Open text field | J9: Yes | K9: Yes | L9: Yes
A10: A-70 | C10: What is the Zip Code (Code postal)? | F10: 1 | G10: A-70 Zipcode | H10: SINGLE SELECTION | I10: Open text field | J10: Yes | K10: Yes | L10: Yes

Sheet Outlet details
A1: Question fields | G1: Answer fields | J1: Backoffice | M1: Comments
A2: ID | B2: Visibility rule | C2: QUESTION WORDING EN | D2: QUESTION WORDING FRENCH | E2: Wording change | F2: Question Priority 1 Keep 0 Discuss -1 remove ? | G2: Reporting LABEL | H2: ANSWER TYPE | I2: ANSWER OPTIONS | J2: Visible ENUMERATOR | K2: VISIBLE BC | L2: PREFILLED FOR BC | M2: ___ | N2: CSD | O2: Dev-team
A3: Section
A4: O-10 | C4: GPS location of outlet | D4: Coordonnées GPS du point de vente | F4: 1 | G4: O-10 GPS | H4: SYSTEM | I4: Device automatically captures | J4: Yes | K4: Yes | L4: Yes
A5: O-40 | C5: What is the address/landmark point that identifies the outlet? (e.g. NEAR THIS... NEXT TO... BEHIND THIS...) | D5: Quel est l'adresse / le point de repere du point de vente ? (A côté de …, après …, derrière ….) | F5: 1 | G5: O-40 Landmark | H5: TEXT | I5: Open verbatim field | J5: Yes | K5: Yes | L5: Yes
A6: O-41 | C6: What is the Street Name? | D6: Quel est le nom de la rue où se trouve le point de vente ? | F6: 1 | G6: O-41 Street | H6: TEXT | I6: Open verbatim field | J6: Yes | K6: Yes | L6: Yes
A7: O-42 | C7: What is the Building No? | D7: Quel est le numéro du batiment où se trouve le point de vente ? | F7: -1 | G7: O-42 Bldg no | H7: TEXT | I7: Open verbatim field | J7: Yes | K7: Yes | L7: Yes
A8: O-43 | C8: What is the Shop No? | D8: Quel est le numéro du point de vente ? | F8: -1 | G8: O-43 Shop no | H8: TEXT | I8: Open verbatim field | J8: Yes | K8: Yes | L8: Yes
A9: O-50 | C9: What is the Enumerated Area you are in? | F9: -1 | G9: O-50 EA | H9: TEXT | I9: Open verbatim field | J9: Yes | K9: Yes | L9: Yes
A10: O-60 | C10: What is the name of the outlet? | D10: Quel est le Nom du point de vente ? | F10: 1 | G10: O-60 Outlet Name | H10: TEXT | I10: Open verbatim field | J10: Yes | K10: Yes | L10: Yes
A11: O-61 | C11: What other name is this outlet known by? | D11: Quel autre Nom designe le point de vente ? | F11: 1 | G11: O-61 Addional Name | H11: TEXT | J11: Yes | K11: Yes | L11: Yes

Sheet Interview Start
A1: Question fields | G1: Answer fields | J1: Backoffice | M1: Comments
A2: ID | B2: Visibility rule | C2: QUESTION WORDING EN | D2: QUESTION WORDING FRENCH | E2: Wording change | F2: Question Priority 1 Keep 0 Discuss -1 remove ? | G2: Reporting LABEL | H2: ANSWER TYPE | I2: ANSWER OPTIONS | J2: Visible ENUMERATOR | K2: VISIBLE BC | L2: PREFILLED FOR BC | M2: ___ | N2: CSD | O2: Dev-team
A3: Section
A4: I-10 | C4: Find the most senior person available (Manager or Owner) | D4: Trouver la personne la plus expérimentée disponible (gérant ou propriétaire) | F4: 1 | G4: I-10 Note | H4: NOTE | J4: Yes | K4: Yes | L4: No
A5: I-20 | C5: Who are you speaking to? | D5: A qui parlez-vous ? | F5: 1 | G5: I-20 Interviewee Role | H5: SINGLE SELECTION | I5: Interviewee Roles | J5: Yes | K5: Yes | L5: Yes
A6: I-30 | C6: INTRODUCTION: My name is .… Our company is operating a Trade Census. The objective is to better understand the tobacco market to eventually improve service to you as point of sale. | D6: INTRODUCTION : Je m'appelle .… Notre société procède à un recensement commercial. L'objectif est de mieux comprendre le marché du tabac pour éventuellement améliorer le service qui vous est offert en tant que point de vente. | F6: 1 | G6: I-30 Note | H6: NOTE | J6: Yes | K6: Yes | L6: No
A7: I-31 | C7: A colleague of mine has recently visited you to conduct a Trade Census, and to insure we have quality information I am checking that we have correctly captured the information about your point of sale. I will be asking you a select number of questions for quality purposes. | D7: Un de mes collègues vous a récemment rendu visite pour effectuer un recensement commercial, et pour nous assurer que nous avons des informations de qualité, je vérifie que nous avons correctement saisi les informations sur votre point de vente. Je vais vous poser un certain nombre de questions à des fins de qualité. | F7: 1 | G7: I-31 Note | H7: NOTE | J7: No | K7: Yes | L7: No
A8: I-40 | C8: Would you have a few minutes available to answer some questions about your business? This should not take long. | D8: Auriez-vous quelques minutes à disposition pour répondre à quelques questions sur votre entreprise ? Cela ne devrait pas prendre longtemps. | F8: 1 | G8: I-40 Survey Compleness | H8: SINGLE SELECTION | I8: Continue Survey | J8: Yes | K8: Yes | L8: No
A9: NEW PAGE
A10: I-130 | C10: Are most (over 50%) of your sales to: | D10: Dans la plupart des cas (plus de 50 %) de vos ventes sont : | F10: 1 | G10: I-130 Segment | H10: SINGLE SELECTION | I10: Segment Options | J10: Yes | K10: Yes | L10: No
A11: I-134 | C11: Do you sell Cigarettes ? | F11: 1 | G11: I-134 Sell Cigarette | H11: SINGLE SELECTION | I11: Yes/No | J11: Yes | K11: Yes | L11: No | N11: If no, go to end section
A12: I-131 | B12: I-130 = "SEG1" | C12: Select the retailer channel | D12: Selectionnez le canal du détaillant | F12: 1 | G12: I-131 Retailer Channel | H12: SINGLE SELECTION | I12: Retailer Channels | J12: Yes | K12: Yes | L12: No
A13: I-132 | B13: I-130 = 2 (OFF TRADE) | C13: Select the Off-Trade channel | F13: -1 | G13: I-132 OFF Channel | H13: SINGLE SELECTION | I13: OFF Channels | J13: Yes | K13: Yes | L13: No
A14: I-133 | B14: I-130 = "SEG1" | C14: Select the wholesaler channel | D14: Selectionnez le type du grossiste | F14: 1 | G14: I-133 Wholesaler Channel | H14: SINGLE SELECTION | I14: Wholesaler Channels | J14: Yes | K14: Yes | L14: No
A15: I-1351 | B15: I-130 = "SEG1" | C15: Are you also distributing to other retailer ? | D15: Vendez-vous aux autres points de vente ? | F15: 1 | G15: I-1351 Outlet Retailer | H15: SINGLE SELECTION | I15: Yes/No | J15: Yes | K15: Yes
A16: I-1352 | B16: I-130 = "SEG1" | C16: Are you also distributing to consumers? | D16: Vendez-vous aux consommateurs ? | F16: 1 | G16: I-135 Outlet Consumer | H16: SINGLE SELECTION | I16: Yes/No | J16: Yes | K16: Yes
A17: I-136 | C17: Do you sell more in sticks, packs or bundle ? | D17: Vendez vous plus en tiges, en paquets ou en cartouches ? | F17: 1 | G17: I-136 Sell other Outlets | H17: SINGLE SELECTION | I17: PT | J17: Yes | K17: Yes
A20: I-401 | C20: Is the outlet part of a chain? | D20: هل المحل جزء من سلسلة؟ | F20: -1
A21: I-402 | C21: What chain does the outlet belong to? | D21: واش هي السلسلة الي تابع ليها المحل؟ | F21: -1
A22: I-403 | C22: What is the chain code? | D22: واش هو رمز السلسلة؟ | F22: -1
A23: I-404 | C23: What is the chain size (# of outlets belong to this chain)? | D23: واش هو حجم السلسلة (عدد المحلات اللي تابعة إلى هذه السلسلة)؟ | F23: -1
A24: I-405 | C24: Does the outlet belong to Group/Group Owenrship? | D24: هل ينتمي المحل إلى مجموعة / مجموعة شركاء؟ | F24: -1

Sheet Volume
A1: Question fields | F1: Answer fields | I1: Backoffice | L1: Visibility | O1: Comments
A2: ID | B2: Visibility rule | C2: QUESTION WORDING EN | D2: QUESTION WORDING ARABIC | E2: Question Priority 1 Keep 0 Discuss -1 remove ? | F2: Reporting LABEL | G2: ANSWER TYPE | H2: ANSWER OPTIONS | I2: Visible ENUMERATOR | J2: VISIBLE BC | K2: PREFILLED FOR BC | L2: VISIBLE IF ON-TRADE | M2: VISIBLE IF OFF-TRADE | N2: VISIBLE IF RTM | O2: ___ | P2: CSD | Q2: Dev-team
A3: Section | B3: I-40 = "CO-1"
A4: V-12 | C4: Do you sell Soft Drinks? | E4: -1 | G4: SINGLE SELECTION | H4: Yes/No | J4: Yes | K4: No | L4: YES | M4: YES | N4: YES
A5: V-13 | C5: Do you sell Beer? | E5: -1 | G5: SINGLE SELECTION | H5: Yes/No | J5: Yes | K5: No | L5: YES | M5: YES | N5: YES
A6: V-14 | C6: Do you sell Spirits or Wines? | E6: -1 | G6: SINGLE SELECTION | H6: Yes/No | J6: Yes | K6: No | L6: YES | M6: YES | N6: YES
A8: V-10 | C8: Do you sell shisha? | D8: Vendez-vous la shisha ? | E8: -1 | F8: V-10 Shisha | G8: SINGLE SELECTION | H8: Yes/No
A9: V-20 | C9: Do you sell evapes? | D9: Vendez-vous des vapoteurs ? | E9: 1 | F9: V-20 evapes | G9: SINGLE SELECTION | H9: Yes/No
A10: V-30 | C10: Do you sell electronic cigarettes? | D10: Vendez-vous des cigarettes electroniques ? | E10: -1 | F10: V-30 E-cigarettes | G10: SINGLE SELECTION | H10: Yes/No
A11: V-50 | C11: On an average week how much do you sell cigarettes (Tobacco) ? | D11: Pendant une semaine normale combien vendez-vous de cigarettes (en Paquets ou en Cartouches) ? | E11: 1 | F11: V-150 Category | G11: MULTIPLE NUMERICAL FIELDS | H11: Options: see Categories list | I11: Yes | J11: Yes | K11: No | L11: YES | M11: YES | N11: YES
A13: V-20 | B13: I-130 = 1 | C13: Price per pack/bundle | D13: Prix par pack/bundle | E13: 0 | F13: V-20 Note | G13: NOTE | I13: Yes | J13: Yes | K13: No
A14: V-21 | B14: I-130 = 2 | C14: Price per bundle/carton | D14: Prix par bundle/carton | E14: 0 | F14: V-21 Note | G14: NOTE | I14: Yes | J14: Yes | K14: No
A15: V-60 | C15: On a normal day, how much do you sell for each cigarette (in packs or cartons)? | D15: Pendant une journée normale, combien vendez vous chacune des cigarettes (En Paquets ou en Cartouches) ? | E15: 1 | F15: V-60 Volume SKU | G15: MULTIPLE NUMERICAL FIELDS | H15: See Categories SKUs lists | I15: Yes | J15: Yes | K15: No | L15: YES | M15: YES | N15: YES
A17: V-61 | C17: On an average week, how much do you sell in sticks ? | D17: Pendant une semaine normale combien de sticks vendez vous ? | E17: -1 | F17: V-61 Sticks Sold | G17: SINGLE SELECTION | H17: PT
A18: V-62 | C18: On an average week, how much do you sell in packs ? | D18: Pendant une semaine normale combien de paquets vendez vous ? | E18: -1 | F18: V-62 Packs Sold | G18: SINGLE SELECTION
A20: V-70 | C20: On an average week how much do you sell of the following Shishas? | D20: Pendant une semaine normale, combien vendez vous chacune des shisha ? | E20: -1 | F20: V-70 Shishas | G20: MULTIPLE NUMERICAL FIELDS | I20: Yes | J20: Yes | K20: No | L20: YES | M20: YES | N20: YES
C21: How much stock of cigarette do you have ? | E21: -1 | G21: MULTIPLE NUMERICAL FIELDS | H21: See Categories SKUs lists
C22: On an average day how much do you sell of the following Cigarettes ( in pack)? | E22: -1

Sheet Wholesaler
A1: Question fields | F1: Answer fields | I1: Backoffice | L1: Comments
A2: ID | B2: Visibility rule | C2: QUESTION WORDING EN | D2: QUESTION WORDING FRENCH | E2: Question Priority 1 Keep 0 Discuss -1 remove ? | F2: Reporting LABEL | G2: ANSWER TYPE | H2: ANSWER OPTIONS | I2: Visible ENUMERATOR | J2: VISIBLE BC | K2: PREFILLED FOR BC | L2: ___ | M2: CSD | N2: Dev-team | O2: CSD | P2: CSD
A3: Section | B3: I-40 = "CO-1" and I-130 = "SEG-2"
A4: W-10 | C4: Who are your customers? | D4: Qui sont vos clients ? | E4: 1 | F4: W-10 WHS Customers | G4: MULTIPLE SELECTION | H4: Whosailer Customer | I4: Yes | J4: Yes | K4: No
A5: W-20 | B5: W-10 e-or ["WCU-1", "WCU-2", "WCU-3", "WCU-4", "WCU-5"] | C5: How many retailers do you service? | D5: Combien de points de vente/détaillants servez-vous ? | E5: 1 | F5: W-20 Num Retailers | G5: NUMERIC | H5: Open numeric field | I5: Yes | J5: No | K5: No
A6: W-30 | B6: W-10 e ["WCU-6"] | C6: How many sub wholesalers do you service? | D6: Combien de semi-grossiste servez-vous ? | E6: 1 | F6: W-30 Num SubWHS | G6: NUMERIC | H6: Open numeric field | I6: Yes | J6: Yes | K6: No
A7: W-40 | B7: W-10 = 3 | C7: How many other type of clients do you service? | E7: 0 | F7: W-10 WHS Customers | G7: NUMERIC | H7: Open numeric field | I7: Yes | J7: Yes | K7: No
A8: W-41 | C8: Do you have an updated overview/list of your customers and their accounts? | E8: 0 | F8: W-41 Consumer List | G8: SINGLE SELECTION | H8: Yes/No | I8: Yes | J8: Yes | K8: Yes
A10: W-50 | C10: What are the top retailer types / channels you service? Choose from a maximum of 3. | E10: -1 | F10: W-50 Top Retailers | G10: MULTIPLE SELECTION (max 3) | H10: Customers Wholesalers | I10: Yes | J10: No | K10: No
A12: W-60 | C12: Do you help with any supplier activations/ promotions? | E12: -1 | G12: SINGLE SELECTION | H12: Yes/No | J12: No | K12: No
A13: W-70 | C13: Do you have a sales/delivery team? | D13: Avez-vous une équipe de vente / livraison ? | E13: 1 | F13: W-70 Sales Team | G13: SINGLE SELECTION | H13: Yes/No | I13: Yes | J13: No | K13: No
A14: W-80 | C14: Does your sales team work with a routing/journey plan? | E14: -1 | F14: W-80 Route Plan | G14: SINGLE SELECTION | H14: Yes/No | I14: Yes | J14: No | K14: No
A15: W-90 | C15: What are the responsibilities of the sales team? | E15: -1 | F15: W-90 ST Responsibility | G15: MULTIPLE SELECTION (min 1, max 3) | H15: See Sales Team Responsibility List | I15: Yes | J15: No | K15: No
A16: W-100 | C16: Do you incentivise your sales reps? | E16: -1 | F16: W-100 SR Incentives | G16: SINGLE SELECTION | H16: Yes/No | I16: Yes | J16: No | K16: No
A18: W-110 | C18: How many people work for your business? | D18: Combien de personnes travaillent pour votre entreprise ? | E18: 1 | F18: W-110 Num Employees | G18: NUMERIC | H18: Open numeric field | I18: Yes | J18: Yes | K18: No
A19: W-120 | B19: W-110 is > 0 | C19: How many people accross the departments? | E19: -1 | G19: MULTIPLE NUMERICAL FIELDS | H19: See Departments List | J19: Yes | K19: No
A21: W-130 | C21: Do you offer credit terms? | E21: -1 | F21: W-130 Credit Terms | G21: SINGLE SELECTION | H21: Yes/No | I21: Yes | J21: No | K21: No
A22: W-131 | B22: W-130 = Yes | C22: What type of credit do you offer? | E22: -1 | F22: W-131 Type of Credit | G22: MULTIPLE SELECTION | H22: See Type of Credit List | I22: Yes | J22: No | K22: No
A23: W-132 | B23: W-131 = 2 | C23: How long is the credit in weeks? | E23: 0 | F23: W-132 Credit Length | G23: NUMERIC | H23: Open numeric field | I23: Yes | J23: No | K23: No
A24: W-133 | B24: W-131 = 1 | C24: What's the minimum value of invoices open for credit? | E24: 0 | F24: W-133 Num Invoices | G24: NUMERIC | H24: Open numeric field | I24: Yes | J24: No | K24: No
A25: W-140 | C25: How do you take the majority of your orders? Choose a maximum of 2. | E25: -1 | F25: W-140 Order Methods | G25: MULTIPLE SELECTION (min 1, max 2) | H25: See Order Methods List | I25: Yes | J25: No | K25: No
A26: W-141 | B26: I-133 = 1 | C26: How much of your sales are for consumer at retail price or for retailers at wholesale price? | E26: -1 | F26: W-141 Selling Mode | G26: SINGLE SELECTION | H26: Selling Mode | I26: Yes | J26: No | K26: No
A27: W-142 | C27: Do you deliver to your clients? | E27: -1 | F27: W-142 Client Delivery | G27: SINGLE SELECTION | H27: Yes/No | I27: Yes | J27: No | K27: No
A28: W-143 | B28: W-142 = Yes | C28: How are your cigarettes delivered to your customers? | E28: -1 | F28: W-143 Delivery Methods | G28: SINGLE SELECTION | H28: Delivery Mode | I28: Yes | J28: No | K28: No
A30: W-150 | C30: Do you have a forecast in place for your sales? | E30: -1 | G30: SINGLE SELECTION | H30: Yes/No | J30: No | K30: No
A31: W-160 | C31: How often do you buy per week (inbound stock)? Enter a number between 0 and 7 | D31: À quelle fréquence achetez-vous par semaine (stock entrant) ? Entrez un nombre entre 0 et 7. | E31: 1 | F31: W-160 Purchase Frequency | G31: NUMERIC | H31: Numeric field 0 to 7 | I31: Yes | J31: No | K31: No
A32: W-170 | C32: Do you measure and register your stock? | E32: -1 | F32: W-170 Stock Measurement | G32: SINGLE SELECTION | H32: Yes/No | I32: Yes | J32: No | K32: No
A34: W-180 | C34: How many trucks do you have? | E34: -1 | G34: NUMERIC | H34: Open numeric field | J34: No | K34: No
A35: W-190 | C35: How many vehicles do you have? | D35: Combien de véhicules de livraison avez-vous (Tricycle, moto, vehicules, ...)? | E35: 1 | F35: W-190 Num Vehicles | G35: NUMERIC | H35: Open numeric field | I35: Yes | J35: No | K35: No
A36: W-200 | C36: Do you use a computer for your business? | E36: -1 | F36: W-200 Computers | G36: SINGLE SELECTION | H36: Yes/No | I36: Yes | J36: No | K36: No
A37: W-205 | C37: Do you use a smartphone for your business? | D37: Utilisez-vous un smartphone pour gérer votre point de vente ? | E37: 1 | F37: W-205 smartphone | G37: SINGLE SELECTION | H37: Yes/No | I37: Yes | J37: No | K37: No
A38: W-210 | C38: Do you have internet? | E38: -1 | F38: W-210 Internet | G38: SINGLE SELECTION | H38: Yes/No | I38: Yes | J38: No | K38: No
A39: W-220 | C39: Do you have all-day power? | E39: -1 | F39: W-220 Power | G39: SINGLE SELECTION | H39: Yes/No | I39: Yes | J39: No | K39: No
A41: W-250 | C41: What's the most important thing your supplier should provide you? | D41: Quelle est la chose la plus importante que votre fournisseur devrait vous fournir ? (Maximum 3) | E41: 1 | F41: W-250 Supplier Support | G41: SINGLE SELECTION | H41: Supplier Support | I41: Yes | J41: No | K41: No
A42: W-260 | C42: Which brands of fridges are present in the outlet | E42: -1 | F42: W-260 W Cooler Available | G42: MULITPLE SELECTION (allow to insert numbers) | H42: See Visibility Brands List | J42: No | K42: No
A44: W-280 | C44: Do you provide credit to your clients? | E44: -1 | G44: SINGLE SELECTION | H44: Yes/No | J44: No | K44: No
A45: W-290 | C45: How many retail clients buy at least once a month from you? | E45: -1 | G45: NUMERIC | H45: Open numeric field | J45: No | K45: No
A46: W-300 | C46: Which beer brand has the most visible branding outside of the outlet with signage ? | E46: -1 | F46: M-30 Most Visible Brand Outside | G46: SINGLE SELECTION | H46: See Visibility Brands List | J46: No | K46: No

Sheet Marketing
A1: Question fields | G1: Answer fields | J1: Backoffice | M1: Comments
A2: ID | B2: Visibility rule | C2: QUESTION WORDING EN | D2: QUESTION WORDING FRENCH | E2: Wording change | F2: Question Priority 1 Keep 0 Discuss -1 remove ? | G2: Reporting LABEL | H2: ANSWER TYPE | I2: ANSWER OPTIONS | J2: Visible ENUMERATOR | K2: VISIBLE BC | L2: PREFILLED FOR BC | M2: ___ | N2: CSD | O2: Dev-team
A3: M-10 | C3: Does the outlet have a checkout? | F3: -1 | H3: SINGLE SELECTION | I3: Yes/No | K3: No | L3: No
A4: M-20 | B4: M-10=Yes | C4: How many of the following type of checkout do you have? | F4: -1 | H4: MULTIPLE NUMERICAL FIELDS | I4: Type Of Fridges | K4: No | L4: No
A5: Section | B5: I-40 = "CO-1" and I-130 ! "SEG-2"
A6: M-24 | C6: On average, how many customers buy cigarettes from your outlet in a day? | D6: En moyenne, combien de clients achètent les cigarettes chez vous par jour ? | F6: 1 | G6: M-24 Customers | H6: NUMERICAL | I6: Open Numeric Field | J6: Yes | K6: No | L6: No
A7: M-30 | C7: Which brand is the MOST visible in the outlet (outside/ inside) ? | D7: Quelle marque de cigarette est la PLUS visible dans le point de vente (extérieur/ intérieur) ? | F7: 1 | G7: M-30 Most Visible Brand | H7: SINGLE SELECTION | I7: Visibility Brands | J7: Yes | K7: No | L7: No
A8: M-31 | C8: Which brand has the MOST visible from inside the outlet? | F8: -1 | G8: M-30 Most Visible Brand Inside | H8: SINGLE SELECTION | I8: Visibility Brands | K8: No | L8: No
A9: M-40 | C9: Does the outlet owner accept visibility items? | F9: -1 | G9: M-50 Display Sign Accepted | H9: SINGLE SELECTION | I9: Yes/No | K9: No | L9: No
A10: M-42 | C10: Is there already a display sign present? Select the type of sign present | F10: -1 | H10: MULTIPLE SELECTION | I10: Dealer Sign | K10: No | L10: No
A11: M-43 | C11: Are pack being displayed ? | D11: Les packs de cigarettes sont-ils visibles ? | F11: 1 | G11: M-43 Pack Displayed | H11: SINGLE SELECTION | I11: Yes/No | J11: Yes | K11: No | L11: No
A12: M-44 | C12: Select the brands that have a wall unit display present | D12: Sélectionnez les marques visibles sur le présentoir à cigarettes encastré dans le mur | F12: 1 | G12: M-44 Wall Display | H12: MULTIPLE NUMERICAL FIELDS | I12: Visibility Brands | K12: No | L12: No
A13: M-45 | C13: Select the brands that have an overhead dispaly present | D13: Sélectionnez les marques visibles sur le présentoir à cigarettes suspendu | F13: 1 | G13: M-45 Overhead Display | H13: MULTIPLE NUMERICAL FIELDS | I13: Visibility Brands | K13: No | L13: No
A14: M-46 | C14: Select the brands that have an standing display present | D14: Sélectionnez les marques visibles sur le présentoir à cigarettes sur pied | F14: 1 | G14: M-46 Standingl Display | H14: MULTIPLE NUMERICAL FIELDS | I14: Visibility Brands | K14: No | L14: No
A15: M-48 | B15: M-42=5 | C15: Select the brands that have a wall painting present | F15: 1 | G15: M-43 Pack Displayed | H15: MULTIPLE NUMERICAL FIELDS | I15: Visibility Brands | K15: No | L15: No
A16: M-49 | B16: M-42=6 | C16: Select the brands that have a free standing display sign present | F16: 1 | G16: M-43 Pack Displayed | H16: MULTIPLE NUMERICAL FIELDS | I16: Visibility Brands | K16: No | L16: No
A17: M-60 | C17: Which of the following brands are present (listed) in the outlet? | F17: 1 | G17: M-43 Pack Displayed | H17: MULTIPLE NUMERICAL FIELDS | I17: Visibility Brands | K17: No | L17: No
A18: M-71 | C18: What are your busiest times of day? (Maximum 2 responses) | F18: 1 | G18: M-43 Pack Displayed | H18: MULTIPLE SELECTION | I18: Time Of The Day | K18: No | L18: No
A19: M-80 | C19: Main gender of consumers | F19: 1 | G19: M-43 Pack Displayed | H19: SINGLE SELECTION | I19: Consumer Gender | K19: No | L19: No
A20: M-90 | C20: Main age of consumers | F20: 1 | G20: M-43 Pack Displayed | H20: SINGLE SELECTION | I20: Consumer Age | K20: No | L20: No
A21: M-100 | C21: Check if following items are present in the outlet (premium indicators) | F21: 1 | G21: M-43 Pack Displayed | H21: MULTIPLE SELECTION | I21: Premium Indicators | K21: No | L21: No
A22: M-116 | C22: What 2 brands from the following list are the most important to you and your consumers? | F22: 1 | G22: M-43 Pack Displayed | H22: MULTIPLE SELECTION (min 2, max 2) | I22: Visibility Brands | K22: No | L22: No
A23: M-117 | C23: What is the year of this outlet's establishment? | F23: 1 | G23: M-43 Pack Displayed
A24: M-118 | C24: What is the number of full time employees? | D24: Combien d'employés à temps plein avez-vous dans votre point de vente ? | F24: 1
A25: M-119 | C25: Is there a storage room available? | D25: Avez-vous un endroit de stockage de la cigarette ? | F25: 1 | G25: M-119 Storage Room | H25: SINGLE SELECTION | I25: Yes/No
A26: M-120 | C26: What is the size of the storage room (in m2)? | D26: Quelle est la superficie de la pièce de stockage (en m2) ? | F26: 1 | G26: M-120 Storage Size | H26: NUMERICAL | I26: Open Numeric Field
A27: M-121 | C27: How many days do you work per week? | D27: Combien de jours travaillez - vous par semaine ? | F27: 1 | G27: M-121 Number Work Days | H27: NUMERICAL | I27: Open Numeric Field | J27: Yes | K27: No | L27: No

Sheet Distribution
A1: Question fields | G1: Answer fields | J1: Backoffice | M1: Comments
A2: ID | B2: Visibility rule | C2: QUESTION WORDING EN | D2: QUESTION WORDING FRENCH | E2: Wording change | F2: Question Priority 1 Keep 0 Discuss -1 remove ? | G2: Reporting LABEL | H2: ANSWER TYPE | I2: ANSWER OPTIONS | J2: Visible ENUMERATOR | K2: VISIBLE BC | L2: PREFILLED FOR BC | M2: ___ | N2: CSD | O2: Dev-team | P2: Min | Q2: Max | R2: Dev-team | S2: The following set of questions will be asked for a minimum of two breweries/companies and a maximum of 9 breweries/companies, please identify the breweries/companies for which you would like to ask the distribution section of the questionnaire, the first brewery is set as an example, we recommend to choose a mix of 5 breweries and 5 soft drink producers
A3: Section | B3: I-40 = "CO-1"
A4: D-10 | C4: ="Where do you mainly source your "&R5&" cigarettes from?" -> Where do you mainly source your cigarettes from? | D4: Où vous approvisionnez-vous principalement en cigarettes JTI? | F4: 1 | G4: D-10 BAT Sourcing | H4: SINGLE SELECTION | I4: cigarettes Sources | J4: Yes | K4: No | L4: No
A5: D-11 | B5: D-10 ! ["SOUR-1"] | C5: How do you make the majority of your orders? | D5: Comment faites-vous HABITUELLEMENT votre commande ? | F5: 1 | G5: D-11 Order Methods | H5: SINGLE SELECTION | I5: Orders Methods | J5: Yes | K5: No | L5: No | S5: 1
A6: D-12 | B6: D-10 ! ["SOUR-1"] | C6: How often do you buy, get delivered per week? | D6: A quelle fréquence achetez-vous/vous faites-vous livrer par semaine ? | F6: 1 | G6: D-12 Purchase Frequency | H6: NUMERIC | I6: Numeric field 0 to 7 | J6: Yes | K6: No | L6: No | P6: 0 | Q6: 7 | S6: 2
A7: D-13 | B7: =A4&"=3,5 or 6" -> D-10=3,5 or 6 | C7: Are you happy with the order quantity and/or frequency? | F7: 0 | H7: SINGLE SELECTION | I7: Yes/No | K7: No | L7: No | S7: 3
A8: D-14 | B8: =A4&"=3,5 or 6" -> D-10=3,5 or 6 | C8: What is the minimum quantity to order to get delivered by a supplier/wholesaler or distributor? | F8: 0 | H8: NUMERIC | I8: Open Numeric Field | K8: No | L8: No | S8: 4
A9: D-15 | B9: =A4&" is not 1" -> D-10 is not 1 | C9: What are your payment conditions? | F9: 0 | H9: SINGLE SELECTION | I9: Payment Condition | K9: No | L9: No | S9: 5
A10: D-16 | B10: =A9&" is not 1" -> D-15 is not 1 | C10: What type of credit do you get? | F10: 0 | H10: MULTIPLE SELECTION | I10: Type of Credit | K10: No | L10: No | S10: 6
A11: D-17 | B11: =A10&" =1" -> D-16 =1 | C11: What is the maximum number of open invoices allowed? | F11: 0 | H11: NUMERIC | I11: Open Numeric Field | K11: No | L11: No | S11: 7
A12: D-18 | B12: =A10&" =2" -> D-16 =2 | C12: How long is the credit in weeks? | F12: 0 | H12: NUMERIC | I12: Numeric field 0 to 52 | K12: No | L12: No | S12: 8
A13: D-19 | B13: D-10 =-or ["SOUR-4", "SOUR-5"] | C13: What is the name of your official Wholesaler/Distributor? | D13: Quel est le nom de votre principal fournisseur pour les produits ? | F13: 1 | G13: D-19 BAT WHS | H13: SINGLE SELECTION | I13: Text box | J13: Yes | K13: No | L13: No | S13: 3
A14: NEW PAGE | S14: 4
A15: D-20 | C15: ="Where do you mainly source your "&R6&" cigarettes from?" -> Where do you mainly source your cigarettes from? | D15: Où vous approvisionnez-vous principalement en cigarettes BAT? | F15: 1 | G15: D-10 PMI Sourcing | H15: SINGLE SELECTION | I15: cigarettes Sources | J15: Yes | K15: No | L15: No | S15: 5
A16: D-21 | B16: D-20 ! ["SOUR-1"] | C16: =C5 -> How do you make the majority of your orders? | D16: Comment faites-vous HABITUELLEMENT votre commande ? | F16: 1 | G16: D-11 Order Methods | H16: SINGLE SELECTION | I16: Orders Methods | J16: Yes | K16: No | L16: No | S16: 6
A17: D-22 | B17: D-20 ! ["SOUR-1"] | C17: =C6 -> How often do you buy, get delivered per week? | D17: A quelle fréquence achetez-vous/vous faites-vous livrer par semaine ? | F17: 1 | G17: D-12 Purchase Frequency | H17: NUMERIC | I17: Numeric field 0 to 7 | J17: Yes | K17: No | L17: No | P17: 0 | Q17: 7 | S17: 7
A18: D-23 | B18: =A15&"=3,5 or 6" -> D-20=3,5 or 6 | C18: =C7 -> Are you happy with the order quantity and/or frequency? | F18: 1 | H18: SINGLE SELECTION | I18: Yes/No | K18: No | L18: No | S18: 8
A19: D-24 | B19: =A15&"=3,5 or 6" -> D-20=3,5 or 6 | C19: =C8 -> What is the minimum quantity to order to get delivered by a supplier/wholesaler or distributor? | F19: 1 | H19: NUMERIC | I19: Open Numeric Field | K19: No | L19: No | S19: 9
A20: D-25 | B20: =A15&" is not 1" -> D-20 is not 1 | C20: =C9 -> What are your payment conditions? | F20: 0 | H20: SINGLE SELECTION | I20: Payment Condition | K20: No | L20: No | S20: 10
A21: D-26 | B21: =A20&" is not 1" -> D-25 is not 1 | C21: =C10 -> What type of credit do you get? | F21: 0 | H21: MULTIPLE SELECTION | I21: Type of Credit | K21: No | L21: No | S21: 11
A22: D-27 | B22: =A21&" =1" -> D-26 =1 | C22: =C11 -> What is the maximum number of open invoices allowed? | F22: 0 | H22: NUMERIC | I22: Open Numeric Field | K22: No | L22: No | S22: 12
A23: D-28 | B23: =A21&" =2" -> D-26 =2 | C23: =C12 -> How long is the credit in weeks? | F23: 0 | H23: NUMERIC | I23: Numeric field 0 to 52 | K23: No | L23: No | S23: 13
A24: D-29 | B24: D-20 =-or ["SOUR-4", "SOUR-5"] | C24: =C13 -> What is the name of your official Wholesaler/Distributor? | D24: Quel est le nom de votre principal fournisseur pour les produits ? | F24: 1 | G24: D-19 PMI WHS | H24: SINGLE SELECTION | I24: Wholesalers/Distributors | J24: Yes | K24: No | L24: No
A25: NEW PAGE
A26: D-30 | C26: ="Where do you mainly source your "&R13&" cigarettes from?" -> Where do you mainly source your cigarettes from? | D26: Où vous approvisionnez-vous principalement en cigarettes PMI ? | F26: 1 | G26: D-10 JTI Sourcing | H26: SINGLE SELECTION | I26: cigarettes Sources | J26: Yes | K26: No | L26: No
A27: D-31 | B27: D-30 ! ["SOUR-1"] | C27: =C16 -> How do you make the majority of your orders? | D27: Comment faites-vous HABITUELLEMENT votre commande ? | F27: 1 | G27: D-11 Order Methods | H27: SINGLE SELECTION | I27: Orders Methods | J27: Yes | K27: No | L27: No
A28: D-32 | B28: D-30 ! ["SOUR-1"] | C28: =C17 -> How often do you buy, get delivered per week? | D28: A quelle fréquence achetez-vous/vous faites-vous livrer par semaine ? | F28: 1 | G28: D-12 Purchase Frequency | H28: NUMERIC | I28: Numeric field 0 to 7 | J28: Yes | K28: No | L28: No | P28: 0 | Q28: 7
A29: D-33 | B29: =A26&"=3,5 or 6" -> D-30=3,5 or 6 | C29: =C18 -> Are you happy with the order quantity and/or frequency? | F29: 0 | H29: SINGLE SELECTION | I29: Yes/No | K29: No | L29: No
A30: D-34 | B30: =A26&"=3,5 or 6" -> D-30=3,5 or 6 | C30: =C19 -> What is the minimum quantity to order to get delivered by a supplier/wholesaler or distributor? | F30: 0 | H30: NUMERIC | I30: Open Numeric Field | K30: No | L30: No
A31: D-35 | B31: =A26&" is not 1" -> D-30 is not 1 | C31: =C20 -> What are your payment conditions? | F31: 0 | H31: SINGLE SELECTION | I31: Payment Condition | K31: No | L31: No
A32: D-36 | B32: =A31&" is not 1" -> D-35 is not 1 | C32: =C21 -> What type of credit do you get? | F32: 0 | H32: MULTIPLE SELECTION | I32: Type of Credit | K32: No | L32: No
A33: D-37 | B33: =A32&" =1" -> D-36 =1 | C33: =C22 -> What is the maximum number of open invoices allowed? | F33: 0 | H33: NUMERIC | I33: Open Numeric Field | K33: No | L33: No
A34: D-38 | B34: =A32&" =2" -> D-36 =2 | C34: =C23 -> How long is the credit in weeks? | F34: 0 | H34: NUMERIC | I34: Numeric field 0 to 52 | K34: No | L34: No
A35: D-39 | B35: D-30 =-or ["SOUR-4", "SOUR-5"] | C35: =C24 -> What is the name of your official Wholesaler/Distributor? | D35: Quel est le nom de votre principal fournisseur pour les produits ? | F35: 1 | G35: D-19 JTI WHS | H35: SINGLE SELECTION | I35: Wholesalers/Distributors | J35: Yes | K35: No | L35: No
A36: NEW PAGE
A37: D-40 | C37: ="Where do you mainly source your "&R14&" cigarettes from?" -> Where do you mainly source your cigarettes from? | D37: Où vous approvisionnez-vous principalement en cigarettes Oriental ? | F37: 1 | G37: D-10 ITG Sourcing | H37: SINGLE SELECTION | I37: cigarettes Sources | J37: Yes | K37: No | L37: No
A38: D-41 | B38: D-40 ! ["SOUR-1"] | C38: =C27 -> How do you make the majority of your orders? | D38: Comment faites-vous HABITUELLEMENT votre commande ? | F38: 1 | G38: D-11 Order Methods | H38: SINGLE SELECTION | I38: Orders Methods | J38: Yes | K38: No | L38: No
A39: D-42 | B39: D-40 ! ["SOUR-1"] | C39: =C28 -> How often do you buy, get delivered per week? | D39: A quelle fréquence achetez-vous/vous faites-vous livrer par semaine ? | F39: 1 | G39: D-12 Purchase Frequency | H39: NUMERIC | I39: Numeric field 0 to 7 | J39: Yes | K39: No | L39: No | P39: 0 | Q39: 7
A40: D-43 | B40: =A37&"=3,5 or 6" -> D-40=3,5 or 6 | C40: =C29 -> Are you happy with the order quantity and/or frequency? | F40: 0 | H40: SINGLE SELECTION | I40: Yes/No | K40: No | L40: No
...

Sheet End
A1: Question fields | G1: Answer fields | J1: Backoffice | M1: Comments
A2: ID | B2: Visibility rule | C2: QUESTION WORDING EN | D2: QUESTION WORDING ARABIC | E2: Wording change | F2: Question Priority 1 Keep 0 Discuss -1 remove ? | G2: Reporting LABEL | H2: ANSWER TYPE | I2: ANSWER OPTIONS | J2: Visible ENUMERATOR | K2: VISIBLE BC | L2: PREFILLED FOR BC | M2: ___ | N2: CSD | O2: Dev-team
A3: Section
A4: E-10 | B4: I-40 = "Yes" | C4: Note - INTERVIEWER READ THE FOLLOWING TO OWNER/MANAGER: Thank you for participating in our survey. In the coming days, you may be contacted by my supervisor to assess the quality of my work and to answer any questions you may have with respect to this interview. | D4: Note - ENUMERATEUR LIRE CE QUI SUIT AU PROPRIÉTAIRE/GÉRANT : Merci pour votre participation à notre sondage. Dans les prochains jours, vous serez peut-être contacté par mon superviseur afin d'évaluer la qualité de mon travail, de répondre à toutes vos questions concernant cet entretien et vérifier que j'ai correctement saisi les informations sur votre point de vente. | F4: 1 | H4: NOTE | I4: 1. NEXT | K4: YES | L4: Yes
A5: E-20 | C5: May I take a picture of the outside and inside of your outlet? | D5: Puis-je prendre une photo de l'intérieur et de l'extérieur de votre point de vente ? | F5: 1 | H5: NOTE | J5: Yes | K5: No | L5: No
A6: E-21 | C6: Take a picture of the inside | D6: Prendre une photo de l'intérieur | F6: 1 | H6: PHOTOGRAPH | J6: Yes | K6: No | L6: No
A7: E-22 | C7: Take a picture of the outside | D7: Prendre une photo de l'extérieur | F7: 1 | H7: PHOTOGRAPH | J7: Yes | K7: No | L7: No
A8: E-23 | C8: Take a picture of the menu | F8: 1 | H8: PHOTOGRAPH | K8: No | L8: No
A9: E-24 | C9: Take a picture of POSM | F9: 1 | H9: PHOTOGRAPH | K9: No | L9: No
A10: E-25 | C10: Take a picture of draught beer | F10: 1 | H10: PHOTOGRAPH | K10: No | L10: No
A11: E-26 | C11: Take a picture of chiller | F11: 1 | H11: PHOTOGRAPH | K11: No | L11: No
A12: E-27 | C12: Take a picture of the serial number on fridge 1 | F12: 1 | H12: PHOTOGRAPH
A13: E-28 | C13: Take a picture of the serial number on fridge 2 | F13: 1 | H13: PHOTOGRAPH
A14: E-29 | C14: Take a picture of the serial number on fridge 3 | F14: 1 | H14: PHOTOGRAPH
A15: E-30 | C15: What would you say is the outlet quality? | F15: 0 | H15: SINGLE SELECTION
A16: NEW PAGE
A17: E-40 | B17: I-40 = "Yes" | C17: I hereby certify that this interview has been carried out by me according to the instructions I received. | D17: Je certifie par la présente que cet entretien a été réalisé par mes soins conformément aux instructions que j'ai reçues. | F17: 1 | H17: NOTE | J17: Yes | K17: No | L17: No
A18: E-50 | B18: 0-10 = 0 | C18: GPS Location of Outlet | D18: Coordonnées GPS du point de vente | F18: 1 | H18: SYSTEM | I18: Device captures automatically. | J18: Yes | K18: No | L18: No
A19: E-110 | B19: I-40 = "Yes" | C19: May I confirm your telephone number? This way my managers may contact you to check that I have correctly captured the information about your business. | D19: Puis-je confirmer votre numéro de téléphone ? De cette façon, mes responsables peuvent vous contacter pour vérifier que j'ai correctement saisi les informations sur votre entreprise. | F19: 1 | H19: NUMERIC | I19: Open Numeric Field | J19: Yes | K19: Yes | L19: Yes
A20: E-111 | C20: Do you have an additional telephone number just in case? (DON'T INSERT COUNTRYCODE) | D20: Avez-vous un numéro de téléphone supplémentaire au cas où ? (NE PAS INSÉRER LE CODE DE PAYS) | F20: 1 | H20: NUMERIC | I20: Open Numeric Field | J20: Yes | K20: Yes | L20: Yes
A21: E-112 | C21: May I confirm your name and surname? | D21: Puis-je confirmer votre nom et prénom? | F21: 1 | G21: E-112 Interviewee Name | H21: TEXT | J21: Yes | K21: Yes | L21: Yes
A22: E-113 | C22: What is the manager/owner's name? | D22: Quel est le nom du gerant/propriétaire ? | F22: 1 | G22: E-113 Manager Name | H22: TEXT
A23: E-60 | C23: General Comments | D23: Commentaires | F23: 1 | H23: TEXT | I23: Open Verbatim Field | J23: Yes | K23: Yes | L23: Yes
A24: E-70 | C24: Time stamp END Interview | D24: Horodatage de fin d'entretien | F24: 1 | H24: DATE & TIME | I24: Device captures automatically. | J24: Yes | K24: Yes | L24: No

Sheet AREA Level 1
A2: SEQ ID | B2: ID | C2: Name -Reporting | D2: Name - App
A3: 1 | B3: CAM1 | C3: Adamaoua | D3: Adamaoua
A4: 2 | B4: CAM2 | C4: Centre | D4: Centre
A5: 3 | B5: CAM3 | C5: Est | D5: Est
A6: 4 | B6: CAM4 | C6: Extrême-Nord | D6: Extrême-Nord
A7: 5 | B7: CAM5 | C7: Littoral | D7: Littoral
A8: 6 | B8: CAM6 | C8: Nord | D8: Nord
A9: 7 | B9: CAM7 | C9: Nord-Ouest | D9: Nord-Ouest
A10: 8 | B10: CAM8 | C10: Ouest | D10: Ouest
A11: 9 | B11: CAM9 | C11: Sud | D11: Sud
A12: 10 | B12: CAM10 | C12: Sud-Ouest | D12: Sud-Ouest

Sheet Province List
A2: A-10 & A-20 & A-30 | B2: Regions | C2: Regions French | D2: Department / Sub regions | E2: Departement French | F2: Communes | G2: Commune French
A3: =+_xlfn.XLOOKUP(B3,'AREA Level 1'!C:C,'AREA Level 1'!B:B) -> CAM1 | B3: Adamaoua | D3: Mayo-Banyo | F3: Bankim
A4: =+_xlfn.XLOOKUP(B4,'AREA Level 1'!C:C,'AREA Level 1'!B:B) -> CAM1 | B4: Adamaoua | D4: Mayo-Banyo | F4: Banyo
A5: =+_xlfn.XLOOKUP(B5,'AREA Level 1'!C:C,'AREA Level 1'!B:B) -> CAM1 | B5: Adamaoua | D5: Vina | F5: Belel
A6: =+_xlfn.XLOOKUP(B6,'AREA Level 1'!C:C,'AREA Level 1'!B:B) -> CAM1 | B6: Adamaoua | D6: Mbéré | F6: Dir
A7: =+_xlfn.XLOOKUP(B7,'AREA Level 1'!C:C,'AREA Level 1'!B:B) -> CAM1 | B7: Adamaoua | D7: Mbéré | F7: Djohong
A8: =+_xlfn.XLOOKUP(B8,'AREA Level 1'!C:C,'AREA Level 1'!B:B) -> CAM1 | B8: Adamaoua | D8: Faro-et-Déo | F8: Galim-Tignere
A9: =+_xlfn.XLOOKUP(B9,'AREA Level 1'!C:C,'AREA Level 1'!B:B) -> CAM1 | B9: Adamaoua | D9: Faro-et-Déo | F9: Kontcha
A10: =+_xlfn.XLOOKUP(B10,'AREA Level 1'!C:C,'AREA Level 1'!B:B) -> CAM1 | B10: Adamaoua | D10: Vina | F10: Martap
A11: =+_xlfn.XLOOKUP(B11,'AREA Level 1'!C:C,'AREA Level 1'!B:B) -> CAM1 | B11: Adamaoua | D11: Faro-et-Déo | F11: Mayo-Baleo
A12: =+_xlfn.XLOOKUP(B12,'AREA Level 1'!C:C,'AREA Level 1'!B:B) -> CAM1 | B12: Adamaoua | D12: Mayo-Banyo | F12: Mayo-Darle
A13: =+_xlfn.XLOOKUP(B13,'AREA Level 1'!C:C,'AREA Level 1'!B:B) -> CAM1 | B13: Adamaoua | D13: Vina | F13: Mbe
A14: =+_xlfn.XLOOKUP(B14,'AREA Level 1'!C:C,'AREA Level 1'!B:B) -> CAM1 | B14: Adamaoua | D14: Mbéré | F14: Meiganga
... A365: =+_xlfn.XLOOKUP(B365,'AREA Level 1'!C:C,'AREA Level 1'!B:B) -> CAM10 | B365: Sud-Ouest | D365: Fako | F365: West-Coast
A366: =+_xlfn.XLOOKUP(B366,'AREA Level 1'!C:C,'AREA Level 1'!B:B) -> 0
A367: =+_xlfn.XLOOKUP(B367,'AREA Level 1'!C:C,'AREA Level 1'!B:B) -> 0

Sheet Sheet4
A2: A-10 & A-20 & A-30 | B2: Regions | C2: Regions French | D2: Department / Sub regions | E2: Departement French | F2: Communes | G2: Commune French
A3: CAM1 | B3: Adamaoua | D3: Mayo-Banyo | F3: Bankim | G3: =+_xlfn.XLOOKUP(D3,'AREA Level 2'!C:C,'AREA Level 2'!B:B) -> CAM_LV2_1
A4: CAM1 | B4: Adamaoua | D4: Mayo-Banyo | F4: Banyo | G4: =+_xlfn.XLOOKUP(D4,'AREA Level 2'!C:C,'AREA Level 2'!B:B) -> CAM_LV2_1
A5: CAM1 | B5: Adamaoua | D5: Vina | F5: Belel | G5: =+_xlfn.XLOOKUP(D5,'AREA Level 2'!C:C,'AREA Level 2'!B:B) -> CAM_LV2_2
A6: CAM1 | B6: Adamaoua | D6: Mbéré | F6: Dir | G6: =+_xlfn.XLOOKUP(D6,'AREA Level 2'!C:C,'AREA Level 2'!B:B) -> CAM_LV2_3
A7: CAM1 | B7: Adamaoua | D7: Mbéré | F7: Djohong | G7: =+_xlfn.XLOOKUP(D7,'AREA Level 2'!C:C,'AREA Level 2'!B:B) -> CAM_LV2_3
A8: CAM1 | B8: Adamaoua | D8: Faro-et-Déo | F8: Galim-Tignere | G8: =+_xlfn.XLOOKUP(D8,'AREA Level 2'!C:C,'AREA Level 2'!B:B) -> CAM_LV2_4
A9: CAM1 | B9: Adamaoua | D9: Faro-et-Déo | F9: Kontcha | G9: =+_xlfn.XLOOKUP(D9,'AREA Level 2'!C:C,'AREA Level 2'!B:B) -> CAM_LV2_4
A10: CAM1 | B10: Adamaoua | D10: Vina | F10: Martap | G10: =+_xlfn.XLOOKUP(D10,'AREA Level 2'!C:C,'AREA Level 2'!B:B) -> CAM_LV2_2
A11: CAM1 | B11: Adamaoua | D11: Faro-et-Déo | F11: Mayo-Baleo | G11: =+_xlfn.XLOOKUP(D11,'AREA Level 2'!C:C,'AREA Level 2'!B:B) -> CAM_LV2_4
A12: CAM1 | B12: Adamaoua | D12: Mayo-Banyo | F12: Mayo-Darle | G12: =+_xlfn.XLOOKUP(D12,'AREA Level 2'!C:C,'AREA Level 2'!B:B) -> CAM_LV2_1
A13: CAM1 | B13: Adamaoua | D13: Vina | F13: Mbe | G13: =+_xlfn.XLOOKUP(D13,'AREA Level 2'!C:C,'AREA Level 2'!B:B) -> CAM_LV2_2
A14: CAM1 | B14: Adamaoua | D14: Mbéré | F14: Meiganga | G14: =+_xlfn.XLOOKUP(D14,'AREA Level 2'!C:C,'AREA Level 2'!B:B) -> CAM_LV2_3
... A365: CAM10 | B365: Sud-Ouest | D365: Fako | F365: West-Coast | G365: =+_xlfn.XLOOKUP(D365,'AREA Level 2'!C:C,'AREA Level 2'!B:B) -> CAM_LV2_57
A366: 0 | G366: =+_xlfn.XLOOKUP(D366,'AREA Level 2'!C:C,'AREA Level 2'!B:B) -> 0
A367: 0 | G367: =+_xlfn.XLOOKUP(D367,'AREA Level 2'!C:C,'AREA Level 2'!B:B) -> 0

Sheet AREA Level 2
A2: SEQ ID | B2: ID | C2: Name -Reporting | D2: Name - App | E2: Level 1 ID
A3: 1 | B3: =_xlfn.CONCAT("CAM_LV2_",A3) -> CAM_LV2_1 | C3: Mayo-Banyo | D3: Mayo-Banyo | E3: =+_xlfn.XLOOKUP(D3,Sheet4!D:D,Sheet4!A:A) -> CAM1
A4: 2 | B4: =_xlfn.CONCAT("CAM_LV2_",A4) -> CAM_LV2_2 | C4: Vina | D4: Vina | E4: =+_xlfn.XLOOKUP(D4,Sheet4!D:D,Sheet4!A:A) -> CAM1
A5: 3 | B5: =_xlfn.CONCAT("CAM_LV2_",A5) -> CAM_LV2_3 | C5: Mbéré | D5: Mbéré | E5: =+_xlfn.XLOOKUP(D5,Sheet4!D:D,Sheet4!A:A) -> CAM1
A6: 4 | B6: =_xlfn.CONCAT("CAM_LV2_",A6) -> CAM_LV2_4 | C6: Faro-et-Déo | D6: Faro-et-Déo | E6: =+_xlfn.XLOOKUP(D6,Sheet4!D:D,Sheet4!A:A) -> CAM1
A7: 5 | B7: =_xlfn.CONCAT("CAM_LV2_",A7) -> CAM_LV2_5 | C7: Djérem | D7: Djérem | E7: =+_xlfn.XLOOKUP(D7,Sheet4!D:D,Sheet4!A:A) -> CAM1
A8: 6 | B8: =_xlfn.CONCAT("CAM_LV2_",A8) -> CAM_LV2_6 | C8: Mefou-et-Afamba | D8: Mefou-et-Afamba | E8: =+_xlfn.XLOOKUP(D8,Sheet4!D:D,Sheet4!A:A) -> CAM2
A9: 7 | B9: =_xlfn.CONCAT("CAM_LV2_",A9) -> CAM_LV2_7 | C9: Nyong-et-So'o | D9: Nyong-et-So'o | E9: =+_xlfn.XLOOKUP(D9,Sheet4!D:D,Sheet4!A:A) -> CAM2
A10: 8 | B10: =_xlfn.CONCAT("CAM_LV2_",A10) -> CAM_LV2_8 | C10: Mefou-et-Akono | D10: Mefou-et-Akono | E10: =+_xlfn.XLOOKUP(D10,Sheet4!D:D,Sheet4!A:A) -> CAM2
A11: 9 | B11: =_xlfn.CONCAT("CAM_LV2_",A11) -> CAM_LV2_9 | C11: Nyong-et-Mfoumou | D11: Nyong-et-Mfoumou | E11: =+_xlfn.XLOOKUP(D11,Sheet4!D:D,Sheet4!A:A) -> CAM2
A12: 10 | B12: =_xlfn.CONCAT("CAM_LV2_",A12) -> CAM_LV2_10 | C12: Mbam-et-Inoubou | D12: Mbam-et-Inoubou | E12: =+_xlfn.XLOOKUP(D12,Sheet4!D:D,Sheet4!A:A) -> CAM2
A13: 11 | B13: =_xlfn.CONCAT("CAM_LV2_",A13) -> CAM_LV2_11 | C13: Lekié | D13: Lekié | E13: =+_xlfn.XLOOKUP(D13,Sheet4!D:D,Sheet4!A:A) -> CAM2
A14: 12 | B14: =_xlfn.CONCAT("CAM_LV2_",A14) -> CAM_LV2_12 | C14: Haute-Sanaga | D14: Haute-Sanaga | E14: =+_xlfn.XLOOKUP(D14,Sheet4!D:D,Sheet4!A:A) -> CAM2
... A60: 58 | B60: =_xlfn.CONCAT("CAM_LV2_",A60) -> CAM_LV2_58 | C60: Meme | D60: Meme | E60: =+_xlfn.XLOOKUP(D60,Sheet4!D:D,Sheet4!A:A) -> CAM10
A61: 59
A62: 60
A63: 61
A64: 62
A65: 63
A66: 64
A67: 65

Sheet I&M Lists
B1: Question | C1: Code | D1: List name | E1: Question Wording ENGLISH | G1: Question Wording Arabic
B2: I-20 | C2: IR | D2: LST-INTERVIEWEE-ROLE | E2: Interviewee Roles
B3: 1 | C3: =CONCATENATE($C$2,"-",B3) -> IR-1 | E3: Manager | G3: Gérant
B4: 2 | C4: =CONCATENATE($C$2,"-",B4) -> IR-2 | E4: Owner | G4: Propriétaire
B5: 3 | C5: =CONCATENATE($C$2,"-",B5) -> IR-3 | E5: Other | G5: Autre
B8: I-40 | C8: CO | D8: LST-CONTINUE | E8: Continue Survey
B9: 1 | C9: =CONCATENATE($C$8,"-",B9) -> CO-1 | E9: YES - Continue with the survey | G9: Oui - Poursuivre l'entretien
B10: 2 | C10: =CONCATENATE($C$8,"-",B10) -> CO-2 | E10: NO - Appointment | G10: Non - Prise de rendez-vous
B11: 3 | C11: =CONCATENATE($C$8,"-",B11) -> CO-3 | E11: NO - Refused | G11: Non - Refus
B12: 4 | C12: =CONCATENATE($C$8,"-",B12) -> CO-4 | E12: NO - Closed | G12: Non - Fermé
B15: I-130 | C15: SEG | D15: LST-SEGMENT | E15: Segment Options | G15: Segment Options
B16: 1 | C16: =CONCATENATE($C$15,"-",B16) -> SEG-1 | E16: To consumers | G16: Aux consommateurs
B17: 2 | C17: =CONCATENATE($C$15,"-",B17) -> SEG-2 | E17: To other retailers | G17: Aux autres points de vente
B20: PT | C20: DIS | D20: LST-PER-DISTRIBUTION | E20: % Distributor
B21: 1 | C21: =CONCATENATE($C$20,"-",B21) -> DIS-1 | E21: Less than 10% | G21: Moins de 10%
B22: 2 | C22: =CONCATENATE($C$20,"-",B22) -> DIS-2 | E22: Between 10 - 20% | G22: Entre 10 - 20%
B23: 3 | C23: =CONCATENATE($C$20,"-",B23) -> DIS-3 | E23: Between 20 - 30% | G23: Entre 20 - 30%
B24: 4 | C24: =CONCATENATE($C$20,"-",B24) -> DIS-4 | E24: Between 30 - 40% | G24: Entre 30 - 40%
B25: 5 | C25: =CONCATENATE($C$20,"-",B25) -> DIS-5 | E25: Between 40 - 50% | G25: Entre 40 - 50%
B27: W-250 | C27: SUS | D27: LST-SUPPLIER-SUPPORT | E27: Supplier Support
B28: 1 | C28: =CONCATENATE($C$27,"-",B28) -> SUS-1 | E28: Price | G28: Prix
B29: 2 | C29: =CONCATENATE($C$27,"-",B29) -> SUS-2 | E29: Promotion | G29: Promotion
B30: 3 | C30: =CONCATENATE($C$27,"-",B30) -> SUS-3 | E30: Relationship | G30: Relationnel
B31: 4 | C31: =CONCATENATE($C$27,"-",B31) -> SUS-4 | E31: Fast & effective delivery | G31: Livraison rapide & efficace
B32: 5 | C32: =CONCATENATE($C$27,"-",B32) -> SUS-5 | E32: Availability | G32: Disponibilité
B33: 6 | C33: =CONCATENATE($C$27,"-",B33) -> SUS-6 | E33: Activation (activities,materials and equipment) | G33: Activation (activités,materiels et équipements)
B34: 7 | C34: =CONCATENATE($C$27,"-",B34) -> SUS-7 | E34: Merchandising | G34: Merchandising
B35: 8 | C35: =CONCATENATE($C$27,"-",B35) -> SUS-8 | E35: Proximity | G35: Proximité
B36: 9 | C36: =CONCATENATE($C$27,"-",B36) -> SUS-9 | E36: Assortment | G36: Assortiment
B37: 10 | C37: =CONCATENATE($C$27,"-",B37) -> SUS-10 | E37: Quality | G37: Qualité
B39: Multiple | C39: SUP | D39: LST-VISIBLEBRAND | E39: Visibility Brands
B40: 2 | C40: =CONCATENATE($C$39,"-",B40) -> SUP-2 | E40: JTI | G40: JTI
B41: 3 | C41: =CONCATENATE($C$39,"-",B41) -> SUP-3 | E41: BAT | G41: BAT
B42: 4 | C42: =CONCATENATE($C$39,"-",B42) -> SUP-4 | E42: PMI | G42: PMI
B43: 5 | C43: =CONCATENATE($C$39,"-",B43) -> SUP-5 | E43: Oriental | G43: ITG
B44: 6 | C44: =CONCATENATE($C$39,"-",B44) -> SUP-6 | E44: KT&G | G44: SNTA
B45: 7 | C45: =CONCATENATE($C$39,"-",B45) -> SUP-7 | E45: Other | G45: Other Branded
B46: 8 | C46: =CONCATENATE($C$39,"-",B46) -> SUP-8
B47: 9 | C47: =CONCATENATE($C$39,"-",B47) -> SUP-9
B48: 10 | C48: =CONCATENATE($C$39,"-",B48) -> SUP-10
...

Sheet Constants
A1: Answer Options
A2: TEXT
A3: SYSTEM
A4: NOTE
A5: DATE & TIME
A6: PHOTOGRAPH
A7: SINGLE SELECTION
A8: MULTIPLE SELECTION
A9: MULTIPLE SELECTION (min 1, max 2)
A10: MULTIPLE SELECTION (min 1, max 3)
A11: MULTIPLE SELECTION (min 2, max 2)
A12: MULTIPLE SELECTION (max 3)
... A16: GPS

Sheet C&C Lists
A1: IFUQ-10 | B1: Channel Type
A2: 1 | B2: On-Trade
A3: 2 | B3: Off-Trade
A4: 3 | B4: Distributor
A6: IFUQ-20 | B6: Interviewee Role
A7: 1 | B7: Manager
A8: 2 | B8: Owner
A9: 3 | B9: Bartender
A10: 4 | B10: Consumer
A12: IFUQ-40 | B12: Continue Survey
A13: 1 | B13: YES - Continue with the survey
A14: 2 | B14: NO - Appointment
A15: 3 | B15: NO - Refused
A18: VFUQ-10 | B18: Gender
A19: 1 | B19: Male
A20: 2 | B20: Female
A22: VFUQ-20 | B22: Age Group
A23: 1 | B23: 18-24
A24: 2 | B24: 25-34
A25: 3 | B25: 35-44
A26: 4 | B26: 45+
A28: VFUQ-30 | B28: Professional Group
A29: 1 | B29: Employees or Students
A30: 2 | B30: Business People
A31: 3 | B31: Government
A32: 4 | B32: Expat
A33: 5 | B33: All of the above
A35: VFUQ-50 | B35: Educational Level
A36: 1 | B36: No diploma
A37: 2 | B37: High School
A38: 3 | B38: Higher
A40: VFUQ-60 | B40: Purchasing Power
A41: 1 | B41: Low
A42: 2 | B42: Medium
A43: 3 | B43: High
A45: VFUQ-90 | B45: Busiest Hours
A46: 1 | B46: 9am-11am
A47: 2 | B47: 11am-5pm
A48: 3 | B48: 5pm-9pm
A49: 4 | B49: 9pm-1am
...

Sheet C&C Driver Start
A1: Question fields | G1: Answer fields | J1: Backoffice | M1: Comments
A2: ID | B2: Visibility rule | C2: QUESTION WORDING EN | D2: QUESTION WORDING __ | E2: Wording change | F2: Question Priority 1 Keep 0 Discuss -1 remove ? | G2: Reporting LABEL | H2: ANSWER TYPE | I2: ANSWER OPTIONS | J2: Visible ENUMERATOR | K2: VISIBLE BC | L2: PREFILLED FOR BC | M2: ___ | N2: CSD | O2: Dev-team
A3: IFUQ-1 | C3: GPS | H3: GPS | I3: Auto Filled | K3: No
A4: IFUQ-10 | C4: Confirm the channel that you are in | H4: SINGLE SELECTION | I4: Channel Type | K4: No
A5: IFUQ-20 | B5: If IFQ | C5: Who are you speaking to? | H5: SINGLE SELECTION | I5: Interviewee Role | K5: No
A6: IFUQ-30 | B6: I-10=ON or I-10=OFF | C6: INTRODUCTION: My name is .… A colleague of mine has recently visited you to collect information regarding a Trade Census. I would like to have follow-up qualititative survey withyourself and a small number of your consumers. The objective is to assist the company to better understand the market and eventually improve service to you and your consumers | H6: NOTE | I6: 1. NEXT | K6: No
A7: IFUQ-31 | B7: i-10=RTM | C7: INTRODUCTION: My name is ... A colleague of mine has recently visited you to collect information regarding a Trade Census. I would like to have follow-up qualitative survey with yourself. The objective is to assist the company to better understand the distribution landscape, your needs and eventually improve service to you. | H7: NOTE | I7: 1. NEXT | K7: No
A8: IFUQ-32 | B8: I-10=ON or I-10=OFF and IFUQ-20=C | C8: INTRODUCTION: My name is .… Our company is operating a market research analysis. The objective is to assist the company to better understand the market and the consummers. We would like to ask you a few questions as a consumer within this outlet, we will only take a few minutes of your time. | K8: No
A9: IFUQ-40 | C9: Would you have a few minutes available to answer some questions about your business? This should not take long. | H9: SINGLE SELECTION | I9: Continue Survey | K9: No

Sheet C&C Driver
I1: Comments
A2: ID | B2: Visibility rule | C2: QUESTION WORDING EN | D2: QUESTION WORDING __ | E2: REPORTING LABEL | F2: ANSWER TYPE | G2: ANSWER OPTIONS | H2: NOTES | I2: ___ | J2: CSD | K2: Dev-team
A3: Section Situation (header on multiple pages)
A4: VFUQ-10 | B4: (IFUQ-10=1 or2) and (IFUQ-20=C) | C4: Which gender is mostly represented in this outlet? | F4: SINGLE SELECTION | G4: Gender | H4: Observational
A5: VFUQ-20 | B5: (IFUQ-10=1 or2) and (IFUQ-20=C) | C5: Which age group is mostly represented in this outlet? | F5: SINGLE SELECTION | G5: Age Group | H5: Observational
A6: NEW PAGE
A7: VFUQ-30 | B7: (IFUQ-10=1 or2) and (IFUQ-20=C) | C7: Which professional group is mostly represented in this outlet? | F7: SINGLE SELECTION | G7: Professional Group | H7: Observational
A8: VFUQ-40 | B8: (IFUQ-10=1 or2) and (IFUQ-20=C) | C8: What nationality is mostly present in this outlet? | F8: SINGLE SELECTION | H8: Observational
A9: VFUQ-50 | B9: (IFUQ-10=1 or2) and (IFUQ-20=C) | C9: Which educational level is mostly represented in this outlet? | F9: SINGLE SELECTION | G9: Educational Level | H9: Observational
A10: NEW PAGE
A11: VFUQ-60 | B11: (IFUQ-10=1 or2) and (IFUQ-20 != C) | C11: What is the purchasing power of the consumer | F11: SINGLE SELECTION | G11: Purchasing Power | H11: Observational
A12: VFUQ-70 | B12: (IFUQ-10=1 or2) and (IFUQ-20 != C) | C12: Gender of the manager? | F12: SINGLE SELECTION | G12: Gender | H12: Observational
A13: VFUQ-80 | B13: (IFUQ-10=1 or2) and (IFUQ-20 != C) | C13: Age group of the manager? | F13: SINGLE SELECTION | G13: Age Group | H13: Observational
A14: NEW PAGE
